Exception in thread Thread-165602:
Traceback (most recent call last):
  File "/Users/darkmoon/PycharmProjects/SpyderPro/venv/lib/python3.7/site-packages/urllib3/connection.py", line 160, in _new_conn
    (self._dns_host, self.port), self.timeout, **extra_kw)
  File "/Users/darkmoon/PycharmProjects/SpyderPro/venv/lib/python3.7/site-packages/urllib3/util/connection.py", line 57, in create_connection
    for res in socket.getaddrinfo(host, port, family, socket.SOCK_STREAM):
  File "/Library/Frameworks/Python.framework/Versions/3.7/lib/python3.7/socket.py", line 748, in getaddrinfo
    for res in _socket.getaddrinfo(host, port, family, type, proto, flags):
socket.gaierror: [Errno 8] nodename nor servname provided, or not known

During handling of the above exception, another exception occurred:

Traceback (most recent call last):
  File "/Users/darkmoon/PycharmProjects/SpyderPro/venv/lib/python3.7/site-packages/urllib3/connectionpool.py", line 603, in urlopen
    chunked=chunked)
  File "/Users/darkmoon/PycharmProjects/SpyderPro/venv/lib/python3.7/site-packages/urllib3/connectionpool.py", line 344, in _make_request
    self._validate_conn(conn)
  File "/Users/darkmoon/PycharmProjects/SpyderPro/venv/lib/python3.7/site-packages/urllib3/connectionpool.py", line 843, in _validate_conn
    conn.connect()
  File "/Users/darkmoon/PycharmProjects/SpyderPro/venv/lib/python3.7/site-packages/urllib3/connection.py", line 316, in connect
    conn = self._new_conn()
  File "/Users/darkmoon/PycharmProjects/SpyderPro/venv/lib/python3.7/site-packages/urllib3/connection.py", line 169, in _new_conn
    self, "Failed to establish a new connection: %s" % e)
urllib3.exceptions.NewConnectionError: <urllib3.connection.VerifiedHTTPSConnection object at 0x107df6dd8>: Failed to establish a new connection: [Errno 8] nodename nor servname provided, or not known

During handling of the above exception, another exception occurred:

Traceback (most recent call last):
  File "/Users/darkmoon/PycharmProjects/SpyderPro/venv/lib/python3.7/site-packages/requests/adapters.py", line 449, in send
    timeout=timeout
  File "/Users/darkmoon/PycharmProjects/SpyderPro/venv/lib/python3.7/site-packages/urllib3/connectionpool.py", line 641, in urlopen
    _stacktrace=sys.exc_info()[2])
  File "/Users/darkmoon/PycharmProjects/SpyderPro/venv/lib/python3.7/site-packages/urllib3/util/retry.py", line 399, in increment
    raise MaxRetryError(_pool, url, error or ResponseError(cause))
urllib3.exceptions.MaxRetryError: HTTPSConnectionPool(host='heat.qq.com', port=443): Max retries exceeded with url: /api/getHeatDataByTime.php?region_id=1230&datetime=2018-07-30+00%3A05%3A00&sub_domain= (Caused by NewConnectionError('<urllib3.connection.VerifiedHTTPSConnection object at 0x107df6dd8>: Failed to establish a new connection: [Errno 8] nodename nor servname provided, or not known'))

During handling of the above exception, another exception occurred:

Traceback (most recent call last):
  File "/Library/Frameworks/Python.framework/Versions/3.7/lib/python3.7/threading.py", line 917, in _bootstrap_inner
    self.run()
  File "spyderpro/people2.py", line 221, in run
    result = self._target(*self._args)
  File "spyderpro/people2.py", line 179, in count_headdata
    g = self.__get_heatdata_bytime(date, datetim, region_id)
  File "spyderpro/people2.py", line 167, in __get_heatdata_bytime
    g = self.request_heatdata(url)
  File "spyderpro/people2.py", line 151, in request_heatdata
    response = self.request.get(url=url, headers=self.headers)
  File "/Users/darkmoon/PycharmProjects/SpyderPro/venv/lib/python3.7/site-packages/requests/sessions.py", line 546, in get
    return self.request('GET', url, **kwargs)
  File "/Users/darkmoon/PycharmProjects/SpyderPro/venv/lib/python3.7/site-packages/requests/sessions.py", line 533, in request
    resp = self.send(prep, **send_kwargs)
  File "/Users/darkmoon/PycharmProjects/SpyderPro/venv/lib/python3.7/site-packages/requests/sessions.py", line 646, in send
    r = adapter.send(request, **kwargs)
  File "/Users/darkmoon/PycharmProjects/SpyderPro/venv/lib/python3.7/site-packages/requests/adapters.py", line 516, in send
    raise ConnectionError(e, request=request)
requests.exceptions.ConnectionError: HTTPSConnectionPool(host='heat.qq.com', port=443): Max retries exceeded with url: /api/getHeatDataByTime.php?region_id=1230&datetime=2018-07-30+00%3A05%3A00&sub_domain= (Caused by NewConnectionError('<urllib3.connection.VerifiedHTTPSConnection object at 0x107df6dd8>: Failed to establish a new connection: [Errno 8] nodename nor servname provided, or not known'))

Exception in thread Thread-167146:
Traceback (most recent call last):
  File "/Users/darkmoon/PycharmProjects/SpyderPro/venv/lib/python3.7/site-packages/urllib3/connection.py", line 160, in _new_conn
    (self._dns_host, self.port), self.timeout, **extra_kw)
  File "/Users/darkmoon/PycharmProjects/SpyderPro/venv/lib/python3.7/site-packages/urllib3/util/connection.py", line 57, in create_connection
    for res in socket.getaddrinfo(host, port, family, socket.SOCK_STREAM):
  File "/Library/Frameworks/Python.framework/Versions/3.7/lib/python3.7/socket.py", line 748, in getaddrinfo
    for res in _socket.getaddrinfo(host, port, family, type, proto, flags):
socket.gaierror: [Errno 8] nodename nor servname provided, or not known

During handling of the above exception, another exception occurred:

Traceback (most recent call last):
  File "/Users/darkmoon/PycharmProjects/SpyderPro/venv/lib/python3.7/site-packages/urllib3/connectionpool.py", line 603, in urlopen
    chunked=chunked)
  File "/Users/darkmoon/PycharmProjects/SpyderPro/venv/lib/python3.7/site-packages/urllib3/connectionpool.py", line 344, in _make_request
    self._validate_conn(conn)
  File "/Users/darkmoon/PycharmProjects/SpyderPro/venv/lib/python3.7/site-packages/urllib3/connectionpool.py", line 843, in _validate_conn
    conn.connect()
  File "/Users/darkmoon/PycharmProjects/SpyderPro/venv/lib/python3.7/site-packages/urllib3/connection.py", line 316, in connect
    conn = self._new_conn()
  File "/Users/darkmoon/PycharmProjects/SpyderPro/venv/lib/python3.7/site-packages/urllib3/connection.py", line 169, in _new_conn
    self, "Failed to establish a new connection: %s" % e)
urllib3.exceptions.NewConnectionError: <urllib3.connection.VerifiedHTTPSConnection object at 0x107e144e0>: Failed to establish a new connection: [Errno 8] nodename nor servname provided, or not known

During handling of the above exception, another exception occurred:

Traceback (most recent call last):
  File "/Users/darkmoon/PycharmProjects/SpyderPro/venv/lib/python3.7/site-packages/requests/adapters.py", line 449, in send
    timeout=timeout
  File "/Users/darkmoon/PycharmProjects/SpyderPro/venv/lib/python3.7/site-packages/urllib3/connectionpool.py", line 641, in urlopen
    _stacktrace=sys.exc_info()[2])
  File "/Users/darkmoon/PycharmProjects/SpyderPro/venv/lib/python3.7/site-packages/urllib3/util/retry.py", line 399, in increment
    raise MaxRetryError(_pool, url, error or ResponseError(cause))
urllib3.exceptions.MaxRetryError: HTTPSConnectionPool(host='heat.qq.com', port=443): Max retries exceeded with url: /api/getHeatDataByTime.php?region_id=1230&datetime=2018-08-04+08%3A45%3A00&sub_domain= (Caused by NewConnectionError('<urllib3.connection.VerifiedHTTPSConnection object at 0x107e144e0>: Failed to establish a new connection: [Errno 8] nodename nor servname provided, or not known'))

During handling of the above exception, another exception occurred:

Traceback (most recent call last):
  File "/Library/Frameworks/Python.framework/Versions/3.7/lib/python3.7/threading.py", line 917, in _bootstrap_inner
    self.run()
  File "spyderpro/people2.py", line 221, in run
    result = self._target(*self._args)
  File "spyderpro/people2.py", line 179, in count_headdata
    g = self.__get_heatdata_bytime(date, datetim, region_id)
  File "spyderpro/people2.py", line 167, in __get_heatdata_bytime
    g = self.request_heatdata(url)
  File "spyderpro/people2.py", line 151, in request_heatdata
    response = self.request.get(url=url, headers=self.headers)
  File "/Users/darkmoon/PycharmProjects/SpyderPro/venv/lib/python3.7/site-packages/requests/sessions.py", line 546, in get
    return self.request('GET', url, **kwargs)
  File "/Users/darkmoon/PycharmProjects/SpyderPro/venv/lib/python3.7/site-packages/requests/sessions.py", line 533, in request
    resp = self.send(prep, **send_kwargs)
  File "/Users/darkmoon/PycharmProjects/SpyderPro/venv/lib/python3.7/site-packages/requests/sessions.py", line 646, in send
    r = adapter.send(request, **kwargs)
  File "/Users/darkmoon/PycharmProjects/SpyderPro/venv/lib/python3.7/site-packages/requests/adapters.py", line 516, in send
    raise ConnectionError(e, request=request)
requests.exceptions.ConnectionError: HTTPSConnectionPool(host='heat.qq.com', port=443): Max retries exceeded with url: /api/getHeatDataByTime.php?region_id=1230&datetime=2018-08-04+08%3A45%3A00&sub_domain= (Caused by NewConnectionError('<urllib3.connection.VerifiedHTTPSConnection object at 0x107e144e0>: Failed to establish a new connection: [Errno 8] nodename nor servname provided, or not known'))

Exception in thread Thread-189382:
Traceback (most recent call last):
  File "/Users/darkmoon/PycharmProjects/SpyderPro/venv/lib/python3.7/site-packages/urllib3/connection.py", line 160, in _new_conn
    (self._dns_host, self.port), self.timeout, **extra_kw)
  File "/Users/darkmoon/PycharmProjects/SpyderPro/venv/lib/python3.7/site-packages/urllib3/util/connection.py", line 57, in create_connection
    for res in socket.getaddrinfo(host, port, family, socket.SOCK_STREAM):
  File "/Library/Frameworks/Python.framework/Versions/3.7/lib/python3.7/socket.py", line 748, in getaddrinfo
    for res in _socket.getaddrinfo(host, port, family, type, proto, flags):
socket.gaierror: [Errno 8] nodename nor servname provided, or not known

During handling of the above exception, another exception occurred:

Traceback (most recent call last):
  File "/Users/darkmoon/PycharmProjects/SpyderPro/venv/lib/python3.7/site-packages/urllib3/connectionpool.py", line 603, in urlopen
    chunked=chunked)
  File "/Users/darkmoon/PycharmProjects/SpyderPro/venv/lib/python3.7/site-packages/urllib3/connectionpool.py", line 344, in _make_request
    self._validate_conn(conn)
  File "/Users/darkmoon/PycharmProjects/SpyderPro/venv/lib/python3.7/site-packages/urllib3/connectionpool.py", line 843, in _validate_conn
    conn.connect()
  File "/Users/darkmoon/PycharmProjects/SpyderPro/venv/lib/python3.7/site-packages/urllib3/connection.py", line 316, in connect
    conn = self._new_conn()
  File "/Users/darkmoon/PycharmProjects/SpyderPro/venv/lib/python3.7/site-packages/urllib3/connection.py", line 169, in _new_conn
    self, "Failed to establish a new connection: %s" % e)
urllib3.exceptions.NewConnectionError: <urllib3.connection.VerifiedHTTPSConnection object at 0x107e142b0>: Failed to establish a new connection: [Errno 8] nodename nor servname provided, or not known

During handling of the above exception, another exception occurred:

Traceback (most recent call last):
  File "/Users/darkmoon/PycharmProjects/SpyderPro/venv/lib/python3.7/site-packages/requests/adapters.py", line 449, in send
    timeout=timeout
  File "/Users/darkmoon/PycharmProjects/SpyderPro/venv/lib/python3.7/site-packages/urllib3/connectionpool.py", line 641, in urlopen
    _stacktrace=sys.exc_info()[2])
  File "/Users/darkmoon/PycharmProjects/SpyderPro/venv/lib/python3.7/site-packages/urllib3/util/retry.py", line 399, in increment
    raise MaxRetryError(_pool, url, error or ResponseError(cause))
urllib3.exceptions.MaxRetryError: HTTPSConnectionPool(host='heat.qq.com', port=443): Max retries exceeded with url: /api/getHeatDataByTime.php?region_id=1230&datetime=2018-10-20+13%3A45%3A00&sub_domain= (Caused by NewConnectionError('<urllib3.connection.VerifiedHTTPSConnection object at 0x107e142b0>: Failed to establish a new connection: [Errno 8] nodename nor servname provided, or not known'))

During handling of the above exception, another exception occurred:

Traceback (most recent call last):
  File "/Library/Frameworks/Python.framework/Versions/3.7/lib/python3.7/threading.py", line 917, in _bootstrap_inner
    self.run()
  File "spyderpro/people2.py", line 221, in run
    result = self._target(*self._args)
  File "spyderpro/people2.py", line 179, in count_headdata
    g = self.__get_heatdata_bytime(date, datetim, region_id)
  File "spyderpro/people2.py", line 167, in __get_heatdata_bytime
    g = self.request_heatdata(url)
  File "spyderpro/people2.py", line 151, in request_heatdata
    response = self.request.get(url=url, headers=self.headers)
  File "/Users/darkmoon/PycharmProjects/SpyderPro/venv/lib/python3.7/site-packages/requests/sessions.py", line 546, in get
    return self.request('GET', url, **kwargs)
  File "/Users/darkmoon/PycharmProjects/SpyderPro/venv/lib/python3.7/site-packages/requests/sessions.py", line 533, in request
    resp = self.send(prep, **send_kwargs)
  File "/Users/darkmoon/PycharmProjects/SpyderPro/venv/lib/python3.7/site-packages/requests/sessions.py", line 646, in send
    r = adapter.send(request, **kwargs)
  File "/Users/darkmoon/PycharmProjects/SpyderPro/venv/lib/python3.7/site-packages/requests/adapters.py", line 516, in send
    raise ConnectionError(e, request=request)
requests.exceptions.ConnectionError: HTTPSConnectionPool(host='heat.qq.com', port=443): Max retries exceeded with url: /api/getHeatDataByTime.php?region_id=1230&datetime=2018-10-20+13%3A45%3A00&sub_domain= (Caused by NewConnectionError('<urllib3.connection.VerifiedHTTPSConnection object at 0x107e142b0>: Failed to establish a new connection: [Errno 8] nodename nor servname provided, or not known'))

Exception in thread Thread-227211:
Traceback (most recent call last):
  File "/Users/darkmoon/PycharmProjects/SpyderPro/venv/lib/python3.7/site-packages/urllib3/connection.py", line 160, in _new_conn
    (self._dns_host, self.port), self.timeout, **extra_kw)
  File "/Users/darkmoon/PycharmProjects/SpyderPro/venv/lib/python3.7/site-packages/urllib3/util/connection.py", line 57, in create_connection
    for res in socket.getaddrinfo(host, port, family, socket.SOCK_STREAM):
  File "/Library/Frameworks/Python.framework/Versions/3.7/lib/python3.7/socket.py", line 748, in getaddrinfo
    for res in _socket.getaddrinfo(host, port, family, type, proto, flags):
socket.gaierror: [Errno 8] nodename nor servname provided, or not known

During handling of the above exception, another exception occurred:

Traceback (most recent call last):
  File "/Users/darkmoon/PycharmProjects/SpyderPro/venv/lib/python3.7/site-packages/urllib3/connectionpool.py", line 603, in urlopen
    chunked=chunked)
  File "/Users/darkmoon/PycharmProjects/SpyderPro/venv/lib/python3.7/site-packages/urllib3/connectionpool.py", line 344, in _make_request
    self._validate_conn(conn)
  File "/Users/darkmoon/PycharmProjects/SpyderPro/venv/lib/python3.7/site-packages/urllib3/connectionpool.py", line 843, in _validate_conn
    conn.connect()
  File "/Users/darkmoon/PycharmProjects/SpyderPro/venv/lib/python3.7/site-packages/urllib3/connection.py", line 316, in connect
    conn = self._new_conn()
  File "/Users/darkmoon/PycharmProjects/SpyderPro/venv/lib/python3.7/site-packages/urllib3/connection.py", line 169, in _new_conn
    self, "Failed to establish a new connection: %s" % e)
urllib3.exceptions.NewConnectionError: <urllib3.connection.VerifiedHTTPSConnection object at 0x107e14128>: Failed to establish a new connection: [Errno 8] nodename nor servname provided, or not known

During handling of the above exception, another exception occurred:

Traceback (most recent call last):
  File "/Users/darkmoon/PycharmProjects/SpyderPro/venv/lib/python3.7/site-packages/requests/adapters.py", line 449, in send
    timeout=timeout
  File "/Users/darkmoon/PycharmProjects/SpyderPro/venv/lib/python3.7/site-packages/urllib3/connectionpool.py", line 641, in urlopen
    _stacktrace=sys.exc_info()[2])
  File "/Users/darkmoon/PycharmProjects/SpyderPro/venv/lib/python3.7/site-packages/urllib3/util/retry.py", line 399, in increment
    raise MaxRetryError(_pool, url, error or ResponseError(cause))
urllib3.exceptions.MaxRetryError: HTTPSConnectionPool(host='heat.qq.com', port=443): Max retries exceeded with url: /api/getHeatDataByTime.php?region_id=1230&datetime=2019-02-28+22%3A10%3A00&sub_domain= (Caused by NewConnectionError('<urllib3.connection.VerifiedHTTPSConnection object at 0x107e14128>: Failed to establish a new connection: [Errno 8] nodename nor servname provided, or not known'))

During handling of the above exception, another exception occurred:

Traceback (most recent call last):
  File "/Library/Frameworks/Python.framework/Versions/3.7/lib/python3.7/threading.py", line 917, in _bootstrap_inner
    self.run()
  File "spyderpro/people2.py", line 221, in run
    result = self._target(*self._args)
  File "spyderpro/people2.py", line 179, in count_headdata
    g = self.__get_heatdata_bytime(date, datetim, region_id)
  File "spyderpro/people2.py", line 167, in __get_heatdata_bytime
    g = self.request_heatdata(url)
  File "spyderpro/people2.py", line 151, in request_heatdata
    response = self.request.get(url=url, headers=self.headers)
  File "/Users/darkmoon/PycharmProjects/SpyderPro/venv/lib/python3.7/site-packages/requests/sessions.py", line 546, in get
    return self.request('GET', url, **kwargs)
  File "/Users/darkmoon/PycharmProjects/SpyderPro/venv/lib/python3.7/site-packages/requests/sessions.py", line 533, in request
    resp = self.send(prep, **send_kwargs)
  File "/Users/darkmoon/PycharmProjects/SpyderPro/venv/lib/python3.7/site-packages/requests/sessions.py", line 646, in send
    r = adapter.send(request, **kwargs)
  File "/Users/darkmoon/PycharmProjects/SpyderPro/venv/lib/python3.7/site-packages/requests/adapters.py", line 516, in send
    raise ConnectionError(e, request=request)
requests.exceptions.ConnectionError: HTTPSConnectionPool(host='heat.qq.com', port=443): Max retries exceeded with url: /api/getHeatDataByTime.php?region_id=1230&datetime=2019-02-28+22%3A10%3A00&sub_domain= (Caused by NewConnectionError('<urllib3.connection.VerifiedHTTPSConnection object at 0x107e14128>: Failed to establish a new connection: [Errno 8] nodename nor servname provided, or not known'))
Exception in thread Thread-212304:
Traceback (most recent call last):
  File "/Users/darkmoon/PycharmProjects/SpyderPro/venv/lib/python3.7/site-packages/urllib3/connection.py", line 160, in _new_conn
    (self._dns_host, self.port), self.timeout, **extra_kw)
  File "/Users/darkmoon/PycharmProjects/SpyderPro/venv/lib/python3.7/site-packages/urllib3/util/connection.py", line 80, in create_connection
    raise err
  File "/Users/darkmoon/PycharmProjects/SpyderPro/venv/lib/python3.7/site-packages/urllib3/util/connection.py", line 70, in create_connection
    sock.connect(sa)
TimeoutError: [Errno 60] Operation timed out

During handling of the above exception, another exception occurred:

Traceback (most recent call last):
  File "/Users/darkmoon/PycharmProjects/SpyderPro/venv/lib/python3.7/site-packages/urllib3/connectionpool.py", line 603, in urlopen
    chunked=chunked)
  File "/Users/darkmoon/PycharmProjects/SpyderPro/venv/lib/python3.7/site-packages/urllib3/connectionpool.py", line 344, in _make_request
    self._validate_conn(conn)
  File "/Users/darkmoon/PycharmProjects/SpyderPro/venv/lib/python3.7/site-packages/urllib3/connectionpool.py", line 843, in _validate_conn
    conn.connect()
  File "/Users/darkmoon/PycharmProjects/SpyderPro/venv/lib/python3.7/site-packages/urllib3/connection.py", line 316, in connect
    conn = self._new_conn()
  File "/Users/darkmoon/PycharmProjects/SpyderPro/venv/lib/python3.7/site-packages/urllib3/connection.py", line 169, in _new_conn
    self, "Failed to establish a new connection: %s" % e)
urllib3.exceptions.NewConnectionError: <urllib3.connection.VerifiedHTTPSConnection object at 0x10e80d550>: Failed to establish a new connection: [Errno 60] Operation timed out

During handling of the above exception, another exception occurred:

Traceback (most recent call last):
  File "/Users/darkmoon/PycharmProjects/SpyderPro/venv/lib/python3.7/site-packages/requests/adapters.py", line 449, in send
    timeout=timeout
  File "/Users/darkmoon/PycharmProjects/SpyderPro/venv/lib/python3.7/site-packages/urllib3/connectionpool.py", line 641, in urlopen
    _stacktrace=sys.exc_info()[2])
  File "/Users/darkmoon/PycharmProjects/SpyderPro/venv/lib/python3.7/site-packages/urllib3/util/retry.py", line 399, in increment
    raise MaxRetryError(_pool, url, error or ResponseError(cause))
urllib3.exceptions.MaxRetryError: HTTPSConnectionPool(host='heat.qq.com', port=443): Max retries exceeded with url: /api/getHeatDataByTime.php?region_id=554&datetime=2019-01-08+03%3A55%3A00&sub_domain= (Caused by NewConnectionError('<urllib3.connection.VerifiedHTTPSConnection object at 0x10e80d550>: Failed to establish a new connection: [Errno 60] Operation timed out'))

During handling of the above exception, another exception occurred:

Traceback (most recent call last):
  File "/Library/Frameworks/Python.framework/Versions/3.7/lib/python3.7/threading.py", line 917, in _bootstrap_inner
    self.run()
  File "spyderpro/test/people2.py", line 444, in run
    result = self._target(*self._args)
  File "spyderpro/test/people2.py", line 402, in count_headdata
    g = self.__get_heatdata_bytime(date, datetim, region_id)
  File "spyderpro/test/people2.py", line 390, in __get_heatdata_bytime
    g = self.request_heatdata(url)
  File "spyderpro/test/people2.py", line 374, in request_heatdata
    response = self.request.get(url=url, headers=self.headers)
  File "/Users/darkmoon/PycharmProjects/SpyderPro/venv/lib/python3.7/site-packages/requests/sessions.py", line 546, in get
    return self.request('GET', url, **kwargs)
  File "/Users/darkmoon/PycharmProjects/SpyderPro/venv/lib/python3.7/site-packages/requests/sessions.py", line 533, in request
    resp = self.send(prep, **send_kwargs)
  File "/Users/darkmoon/PycharmProjects/SpyderPro/venv/lib/python3.7/site-packages/requests/sessions.py", line 646, in send
    r = adapter.send(request, **kwargs)
  File "/Users/darkmoon/PycharmProjects/SpyderPro/venv/lib/python3.7/site-packages/requests/adapters.py", line 516, in send
    raise ConnectionError(e, request=request)
requests.exceptions.ConnectionError: HTTPSConnectionPool(host='heat.qq.com', port=443): Max retries exceeded with url: /api/getHeatDataByTime.php?region_id=554&datetime=2019-01-08+03%3A55%3A00&sub_domain= (Caused by NewConnectionError('<urllib3.connection.VerifiedHTTPSConnection object at 0x10e80d550>: Failed to establish a new connection: [Errno 60] Operation timed out'))

Exception in thread Thread-326352:
Traceback (most recent call last):
  File "/Users/darkmoon/PycharmProjects/SpyderPro/venv/lib/python3.7/site-packages/urllib3/connection.py", line 160, in _new_conn
    (self._dns_host, self.port), self.timeout, **extra_kw)
  File "/Users/darkmoon/PycharmProjects/SpyderPro/venv/lib/python3.7/site-packages/urllib3/util/connection.py", line 80, in create_connection
    raise err
  File "/Users/darkmoon/PycharmProjects/SpyderPro/venv/lib/python3.7/site-packages/urllib3/util/connection.py", line 70, in create_connection
    sock.connect(sa)
TimeoutError: [Errno 60] Operation timed out

During handling of the above exception, another exception occurred:

Traceback (most recent call last):
  File "/Users/darkmoon/PycharmProjects/SpyderPro/venv/lib/python3.7/site-packages/urllib3/connectionpool.py", line 603, in urlopen
    chunked=chunked)
  File "/Users/darkmoon/PycharmProjects/SpyderPro/venv/lib/python3.7/site-packages/urllib3/connectionpool.py", line 344, in _make_request
    self._validate_conn(conn)
  File "/Users/darkmoon/PycharmProjects/SpyderPro/venv/lib/python3.7/site-packages/urllib3/connectionpool.py", line 843, in _validate_conn
    conn.connect()
  File "/Users/darkmoon/PycharmProjects/SpyderPro/venv/lib/python3.7/site-packages/urllib3/connection.py", line 316, in connect
    conn = self._new_conn()
  File "/Users/darkmoon/PycharmProjects/SpyderPro/venv/lib/python3.7/site-packages/urllib3/connection.py", line 169, in _new_conn
    self, "Failed to establish a new connection: %s" % e)
urllib3.exceptions.NewConnectionError: <urllib3.connection.VerifiedHTTPSConnection object at 0x10e80db70>: Failed to establish a new connection: [Errno 60] Operation timed out

During handling of the above exception, another exception occurred:

Traceback (most recent call last):
  File "/Users/darkmoon/PycharmProjects/SpyderPro/venv/lib/python3.7/site-packages/requests/adapters.py", line 449, in send
    timeout=timeout
  File "/Users/darkmoon/PycharmProjects/SpyderPro/venv/lib/python3.7/site-packages/urllib3/connectionpool.py", line 641, in urlopen
    _stacktrace=sys.exc_info()[2])
  File "/Users/darkmoon/PycharmProjects/SpyderPro/venv/lib/python3.7/site-packages/urllib3/util/retry.py", line 399, in increment
    raise MaxRetryError(_pool, url, error or ResponseError(cause))
urllib3.exceptions.MaxRetryError: HTTPSConnectionPool(host='heat.qq.com', port=443): Max retries exceeded with url: /api/getHeatDataByTime.php?region_id=612&datetime=2017-08-04+04%3A00%3A00&sub_domain= (Caused by NewConnectionError('<urllib3.connection.VerifiedHTTPSConnection object at 0x10e80db70>: Failed to establish a new connection: [Errno 60] Operation timed out'))

During handling of the above exception, another exception occurred:

Traceback (most recent call last):
  File "/Library/Frameworks/Python.framework/Versions/3.7/lib/python3.7/threading.py", line 917, in _bootstrap_inner
    self.run()
  File "spyderpro/test/people2.py", line 444, in run
    result = self._target(*self._args)
  File "spyderpro/test/people2.py", line 402, in count_headdata
    g = self.__get_heatdata_bytime(date, datetim, region_id)
  File "spyderpro/test/people2.py", line 390, in __get_heatdata_bytime
    g = self.request_heatdata(url)
  File "spyderpro/test/people2.py", line 374, in request_heatdata
    response = self.request.get(url=url, headers=self.headers)
  File "/Users/darkmoon/PycharmProjects/SpyderPro/venv/lib/python3.7/site-packages/requests/sessions.py", line 546, in get
    return self.request('GET', url, **kwargs)
  File "/Users/darkmoon/PycharmProjects/SpyderPro/venv/lib/python3.7/site-packages/requests/sessions.py", line 533, in request
    resp = self.send(prep, **send_kwargs)
  File "/Users/darkmoon/PycharmProjects/SpyderPro/venv/lib/python3.7/site-packages/requests/sessions.py", line 646, in send
    r = adapter.send(request, **kwargs)
  File "/Users/darkmoon/PycharmProjects/SpyderPro/venv/lib/python3.7/site-packages/requests/adapters.py", line 516, in send
    raise ConnectionError(e, request=request)
requests.exceptions.ConnectionError: HTTPSConnectionPool(host='heat.qq.com', port=443): Max retries exceeded with url: /api/getHeatDataByTime.php?region_id=612&datetime=2017-08-04+04%3A00%3A00&sub_domain= (Caused by NewConnectionError('<urllib3.connection.VerifiedHTTPSConnection object at 0x10e80db70>: Failed to establish a new connection: [Errno 60] Operation timed out'))

Exception in thread Thread-454061:
Traceback (most recent call last):
  File "/Users/darkmoon/PycharmProjects/SpyderPro/venv/lib/python3.7/site-packages/urllib3/connectionpool.py", line 603, in urlopen
    chunked=chunked)
  File "/Users/darkmoon/PycharmProjects/SpyderPro/venv/lib/python3.7/site-packages/urllib3/connectionpool.py", line 387, in _make_request
    six.raise_from(e, None)
  File "<string>", line 2, in raise_from
  File "/Users/darkmoon/PycharmProjects/SpyderPro/venv/lib/python3.7/site-packages/urllib3/connectionpool.py", line 383, in _make_request
    httplib_response = conn.getresponse()
  File "/Library/Frameworks/Python.framework/Versions/3.7/lib/python3.7/http/client.py", line 1321, in getresponse
    response.begin()
  File "/Library/Frameworks/Python.framework/Versions/3.7/lib/python3.7/http/client.py", line 296, in begin
    version, status, reason = self._read_status()
  File "/Library/Frameworks/Python.framework/Versions/3.7/lib/python3.7/http/client.py", line 265, in _read_status
    raise RemoteDisconnected("Remote end closed connection without"
http.client.RemoteDisconnected: Remote end closed connection without response

During handling of the above exception, another exception occurred:

Traceback (most recent call last):
  File "/Users/darkmoon/PycharmProjects/SpyderPro/venv/lib/python3.7/site-packages/requests/adapters.py", line 449, in send
    timeout=timeout
  File "/Users/darkmoon/PycharmProjects/SpyderPro/venv/lib/python3.7/site-packages/urllib3/connectionpool.py", line 641, in urlopen
    _stacktrace=sys.exc_info()[2])
  File "/Users/darkmoon/PycharmProjects/SpyderPro/venv/lib/python3.7/site-packages/urllib3/util/retry.py", line 368, in increment
    raise six.reraise(type(error), error, _stacktrace)
  File "/Users/darkmoon/PycharmProjects/SpyderPro/venv/lib/python3.7/site-packages/urllib3/packages/six.py", line 685, in reraise
    raise value.with_traceback(tb)
  File "/Users/darkmoon/PycharmProjects/SpyderPro/venv/lib/python3.7/site-packages/urllib3/connectionpool.py", line 603, in urlopen
    chunked=chunked)
  File "/Users/darkmoon/PycharmProjects/SpyderPro/venv/lib/python3.7/site-packages/urllib3/connectionpool.py", line 387, in _make_request
    six.raise_from(e, None)
  File "<string>", line 2, in raise_from
  File "/Users/darkmoon/PycharmProjects/SpyderPro/venv/lib/python3.7/site-packages/urllib3/connectionpool.py", line 383, in _make_request
    httplib_response = conn.getresponse()
  File "/Library/Frameworks/Python.framework/Versions/3.7/lib/python3.7/http/client.py", line 1321, in getresponse
    response.begin()
  File "/Library/Frameworks/Python.framework/Versions/3.7/lib/python3.7/http/client.py", line 296, in begin
    version, status, reason = self._read_status()
  File "/Library/Frameworks/Python.framework/Versions/3.7/lib/python3.7/http/client.py", line 265, in _read_status
    raise RemoteDisconnected("Remote end closed connection without"
urllib3.exceptions.ProtocolError: ('Connection aborted.', RemoteDisconnected('Remote end closed connection without response'))

During handling of the above exception, another exception occurred:

Traceback (most recent call last):
  File "/Library/Frameworks/Python.framework/Versions/3.7/lib/python3.7/threading.py", line 917, in _bootstrap_inner
    self.run()
  File "spyderpro/test/people2.py", line 444, in run
    result = self._target(*self._args)
  File "spyderpro/test/people2.py", line 402, in count_headdata
    g = self.__get_heatdata_bytime(date, datetim, region_id)
  File "spyderpro/test/people2.py", line 390, in __get_heatdata_bytime
    g = self.request_heatdata(url)
  File "spyderpro/test/people2.py", line 374, in request_heatdata
    response = self.request.get(url=url, headers=self.headers)
  File "/Users/darkmoon/PycharmProjects/SpyderPro/venv/lib/python3.7/site-packages/requests/sessions.py", line 546, in get
    return self.request('GET', url, **kwargs)
  File "/Users/darkmoon/PycharmProjects/SpyderPro/venv/lib/python3.7/site-packages/requests/sessions.py", line 533, in request
    resp = self.send(prep, **send_kwargs)
  File "/Users/darkmoon/PycharmProjects/SpyderPro/venv/lib/python3.7/site-packages/requests/sessions.py", line 646, in send
    r = adapter.send(request, **kwargs)
  File "/Users/darkmoon/PycharmProjects/SpyderPro/venv/lib/python3.7/site-packages/requests/adapters.py", line 498, in send
    raise ConnectionError(err, request=request)
requests.exceptions.ConnectionError: ('Connection aborted.', RemoteDisconnected('Remote end closed connection without response'))

Exception in thread Thread-465299:
Traceback (most recent call last):
  File "/Users/darkmoon/PycharmProjects/SpyderPro/venv/lib/python3.7/site-packages/urllib3/connectionpool.py", line 603, in urlopen
    chunked=chunked)
  File "/Users/darkmoon/PycharmProjects/SpyderPro/venv/lib/python3.7/site-packages/urllib3/connectionpool.py", line 387, in _make_request
    six.raise_from(e, None)
  File "<string>", line 2, in raise_from
  File "/Users/darkmoon/PycharmProjects/SpyderPro/venv/lib/python3.7/site-packages/urllib3/connectionpool.py", line 383, in _make_request
    httplib_response = conn.getresponse()
  File "/Library/Frameworks/Python.framework/Versions/3.7/lib/python3.7/http/client.py", line 1321, in getresponse
    response.begin()
  File "/Library/Frameworks/Python.framework/Versions/3.7/lib/python3.7/http/client.py", line 296, in begin
    version, status, reason = self._read_status()
  File "/Library/Frameworks/Python.framework/Versions/3.7/lib/python3.7/http/client.py", line 257, in _read_status
    line = str(self.fp.readline(_MAXLINE + 1), "iso-8859-1")
  File "/Library/Frameworks/Python.framework/Versions/3.7/lib/python3.7/socket.py", line 589, in readinto
    return self._sock.recv_into(b)
  File "/Library/Frameworks/Python.framework/Versions/3.7/lib/python3.7/ssl.py", line 1052, in recv_into
    return self.read(nbytes, buffer)
  File "/Library/Frameworks/Python.framework/Versions/3.7/lib/python3.7/ssl.py", line 911, in read
    return self._sslobj.read(len, buffer)
ConnectionResetError: [Errno 54] Connection reset by peer

During handling of the above exception, another exception occurred:

Traceback (most recent call last):
  File "/Users/darkmoon/PycharmProjects/SpyderPro/venv/lib/python3.7/site-packages/requests/adapters.py", line 449, in send
    timeout=timeout
  File "/Users/darkmoon/PycharmProjects/SpyderPro/venv/lib/python3.7/site-packages/urllib3/connectionpool.py", line 641, in urlopen
    _stacktrace=sys.exc_info()[2])
  File "/Users/darkmoon/PycharmProjects/SpyderPro/venv/lib/python3.7/site-packages/urllib3/util/retry.py", line 368, in increment
    raise six.reraise(type(error), error, _stacktrace)
  File "/Users/darkmoon/PycharmProjects/SpyderPro/venv/lib/python3.7/site-packages/urllib3/packages/six.py", line 685, in reraise
    raise value.with_traceback(tb)
  File "/Users/darkmoon/PycharmProjects/SpyderPro/venv/lib/python3.7/site-packages/urllib3/connectionpool.py", line 603, in urlopen
    chunked=chunked)
  File "/Users/darkmoon/PycharmProjects/SpyderPro/venv/lib/python3.7/site-packages/urllib3/connectionpool.py", line 387, in _make_request
    six.raise_from(e, None)
  File "<string>", line 2, in raise_from
  File "/Users/darkmoon/PycharmProjects/SpyderPro/venv/lib/python3.7/site-packages/urllib3/connectionpool.py", line 383, in _make_request
    httplib_response = conn.getresponse()
  File "/Library/Frameworks/Python.framework/Versions/3.7/lib/python3.7/http/client.py", line 1321, in getresponse
    response.begin()
  File "/Library/Frameworks/Python.framework/Versions/3.7/lib/python3.7/http/client.py", line 296, in begin
    version, status, reason = self._read_status()
  File "/Library/Frameworks/Python.framework/Versions/3.7/lib/python3.7/http/client.py", line 257, in _read_status
    line = str(self.fp.readline(_MAXLINE + 1), "iso-8859-1")
  File "/Library/Frameworks/Python.framework/Versions/3.7/lib/python3.7/socket.py", line 589, in readinto
    return self._sock.recv_into(b)
  File "/Library/Frameworks/Python.framework/Versions/3.7/lib/python3.7/ssl.py", line 1052, in recv_into
    return self.read(nbytes, buffer)
  File "/Library/Frameworks/Python.framework/Versions/3.7/lib/python3.7/ssl.py", line 911, in read
    return self._sslobj.read(len, buffer)
urllib3.exceptions.ProtocolError: ('Connection aborted.', ConnectionResetError(54, 'Connection reset by peer'))

During handling of the above exception, another exception occurred:

Traceback (most recent call last):
  File "/Library/Frameworks/Python.framework/Versions/3.7/lib/python3.7/threading.py", line 917, in _bootstrap_inner
    self.run()
  File "spyderpro/test/people2.py", line 444, in run
    result = self._target(*self._args)
  File "spyderpro/test/people2.py", line 402, in count_headdata
    g = self.__get_heatdata_bytime(date, datetim, region_id)
  File "spyderpro/test/people2.py", line 390, in __get_heatdata_bytime
    g = self.request_heatdata(url)
  File "spyderpro/test/people2.py", line 374, in request_heatdata
    response = self.request.get(url=url, headers=self.headers)
  File "/Users/darkmoon/PycharmProjects/SpyderPro/venv/lib/python3.7/site-packages/requests/sessions.py", line 546, in get
    return self.request('GET', url, **kwargs)
  File "/Users/darkmoon/PycharmProjects/SpyderPro/venv/lib/python3.7/site-packages/requests/sessions.py", line 533, in request
    resp = self.send(prep, **send_kwargs)
  File "/Users/darkmoon/PycharmProjects/SpyderPro/venv/lib/python3.7/site-packages/requests/sessions.py", line 646, in send
    r = adapter.send(request, **kwargs)
  File "/Users/darkmoon/PycharmProjects/SpyderPro/venv/lib/python3.7/site-packages/requests/adapters.py", line 498, in send
    raise ConnectionError(err, request=request)
requests.exceptions.ConnectionError: ('Connection aborted.', ConnectionResetError(54, 'Connection reset by peer'))
