Exception in thread Thread-165602:
Traceback (most recent call last):
  File "/Users/darkmoon/PycharmProjects/SpyderPro/venv/lib/python3.7/site-packages/urllib3/connection.py", line 160, in _new_conn
    (self._dns_host, self.port), self.timeout, **extra_kw)
  File "/Users/darkmoon/PycharmProjects/SpyderPro/venv/lib/python3.7/site-packages/urllib3/util/connection.py", line 57, in create_connection
    for res in socket.getaddrinfo(host, port, family, socket.SOCK_STREAM):
  File "/Library/Frameworks/Python.framework/Versions/3.7/lib/python3.7/socket.py", line 748, in getaddrinfo
    for res in _socket.getaddrinfo(host, port, family, type, proto, flags):
socket.gaierror: [Errno 8] nodename nor servname provided, or not known

During handling of the above exception, another exception occurred:

Traceback (most recent call last):
  File "/Users/darkmoon/PycharmProjects/SpyderPro/venv/lib/python3.7/site-packages/urllib3/connectionpool.py", line 603, in urlopen
    chunked=chunked)
  File "/Users/darkmoon/PycharmProjects/SpyderPro/venv/lib/python3.7/site-packages/urllib3/connectionpool.py", line 344, in _make_request
    self._validate_conn(conn)
  File "/Users/darkmoon/PycharmProjects/SpyderPro/venv/lib/python3.7/site-packages/urllib3/connectionpool.py", line 843, in _validate_conn
    conn.connect()
  File "/Users/darkmoon/PycharmProjects/SpyderPro/venv/lib/python3.7/site-packages/urllib3/connection.py", line 316, in connect
    conn = self._new_conn()
  File "/Users/darkmoon/PycharmProjects/SpyderPro/venv/lib/python3.7/site-packages/urllib3/connection.py", line 169, in _new_conn
    self, "Failed to establish a new connection: %s" % e)
urllib3.exceptions.NewConnectionError: <urllib3.connection.VerifiedHTTPSConnection object at 0x107df6dd8>: Failed to establish a new connection: [Errno 8] nodename nor servname provided, or not known

During handling of the above exception, another exception occurred:

Traceback (most recent call last):
  File "/Users/darkmoon/PycharmProjects/SpyderPro/venv/lib/python3.7/site-packages/requests/adapters.py", line 449, in send
    timeout=timeout
  File "/Users/darkmoon/PycharmProjects/SpyderPro/venv/lib/python3.7/site-packages/urllib3/connectionpool.py", line 641, in urlopen
    _stacktrace=sys.exc_info()[2])
  File "/Users/darkmoon/PycharmProjects/SpyderPro/venv/lib/python3.7/site-packages/urllib3/util/retry.py", line 399, in increment
    raise MaxRetryError(_pool, url, error or ResponseError(cause))
urllib3.exceptions.MaxRetryError: HTTPSConnectionPool(host='heat.qq.com', port=443): Max retries exceeded with url: /api/getHeatDataByTime.php?region_id=1230&datetime=2018-07-30+00%3A05%3A00&sub_domain= (Caused by NewConnectionError('<urllib3.connection.VerifiedHTTPSConnection object at 0x107df6dd8>: Failed to establish a new connection: [Errno 8] nodename nor servname provided, or not known'))

During handling of the above exception, another exception occurred:

Traceback (most recent call last):
  File "/Library/Frameworks/Python.framework/Versions/3.7/lib/python3.7/threading.py", line 917, in _bootstrap_inner
    self.run()
  File "spyderpro/people2.py", line 221, in run
    result = self._target(*self._args)
  File "spyderpro/people2.py", line 179, in count_headdata
    g = self.__get_heatdata_bytime(date, datetim, region_id)
  File "spyderpro/people2.py", line 167, in __get_heatdata_bytime
    g = self.request_heatdata(url)
  File "spyderpro/people2.py", line 151, in request_heatdata
    response = self.request.get(url=url, headers=self.headers)
  File "/Users/darkmoon/PycharmProjects/SpyderPro/venv/lib/python3.7/site-packages/requests/sessions.py", line 546, in get
    return self.request('GET', url, **kwargs)
  File "/Users/darkmoon/PycharmProjects/SpyderPro/venv/lib/python3.7/site-packages/requests/sessions.py", line 533, in request
    resp = self.send(prep, **send_kwargs)
  File "/Users/darkmoon/PycharmProjects/SpyderPro/venv/lib/python3.7/site-packages/requests/sessions.py", line 646, in send
    r = adapter.send(request, **kwargs)
  File "/Users/darkmoon/PycharmProjects/SpyderPro/venv/lib/python3.7/site-packages/requests/adapters.py", line 516, in send
    raise ConnectionError(e, request=request)
requests.exceptions.ConnectionError: HTTPSConnectionPool(host='heat.qq.com', port=443): Max retries exceeded with url: /api/getHeatDataByTime.php?region_id=1230&datetime=2018-07-30+00%3A05%3A00&sub_domain= (Caused by NewConnectionError('<urllib3.connection.VerifiedHTTPSConnection object at 0x107df6dd8>: Failed to establish a new connection: [Errno 8] nodename nor servname provided, or not known'))

Exception in thread Thread-167146:
Traceback (most recent call last):
  File "/Users/darkmoon/PycharmProjects/SpyderPro/venv/lib/python3.7/site-packages/urllib3/connection.py", line 160, in _new_conn
    (self._dns_host, self.port), self.timeout, **extra_kw)
  File "/Users/darkmoon/PycharmProjects/SpyderPro/venv/lib/python3.7/site-packages/urllib3/util/connection.py", line 57, in create_connection
    for res in socket.getaddrinfo(host, port, family, socket.SOCK_STREAM):
  File "/Library/Frameworks/Python.framework/Versions/3.7/lib/python3.7/socket.py", line 748, in getaddrinfo
    for res in _socket.getaddrinfo(host, port, family, type, proto, flags):
socket.gaierror: [Errno 8] nodename nor servname provided, or not known

During handling of the above exception, another exception occurred:

Traceback (most recent call last):
  File "/Users/darkmoon/PycharmProjects/SpyderPro/venv/lib/python3.7/site-packages/urllib3/connectionpool.py", line 603, in urlopen
    chunked=chunked)
  File "/Users/darkmoon/PycharmProjects/SpyderPro/venv/lib/python3.7/site-packages/urllib3/connectionpool.py", line 344, in _make_request
    self._validate_conn(conn)
  File "/Users/darkmoon/PycharmProjects/SpyderPro/venv/lib/python3.7/site-packages/urllib3/connectionpool.py", line 843, in _validate_conn
    conn.connect()
  File "/Users/darkmoon/PycharmProjects/SpyderPro/venv/lib/python3.7/site-packages/urllib3/connection.py", line 316, in connect
    conn = self._new_conn()
  File "/Users/darkmoon/PycharmProjects/SpyderPro/venv/lib/python3.7/site-packages/urllib3/connection.py", line 169, in _new_conn
    self, "Failed to establish a new connection: %s" % e)
urllib3.exceptions.NewConnectionError: <urllib3.connection.VerifiedHTTPSConnection object at 0x107e144e0>: Failed to establish a new connection: [Errno 8] nodename nor servname provided, or not known

During handling of the above exception, another exception occurred:

Traceback (most recent call last):
  File "/Users/darkmoon/PycharmProjects/SpyderPro/venv/lib/python3.7/site-packages/requests/adapters.py", line 449, in send
    timeout=timeout
  File "/Users/darkmoon/PycharmProjects/SpyderPro/venv/lib/python3.7/site-packages/urllib3/connectionpool.py", line 641, in urlopen
    _stacktrace=sys.exc_info()[2])
  File "/Users/darkmoon/PycharmProjects/SpyderPro/venv/lib/python3.7/site-packages/urllib3/util/retry.py", line 399, in increment
    raise MaxRetryError(_pool, url, error or ResponseError(cause))
urllib3.exceptions.MaxRetryError: HTTPSConnectionPool(host='heat.qq.com', port=443): Max retries exceeded with url: /api/getHeatDataByTime.php?region_id=1230&datetime=2018-08-04+08%3A45%3A00&sub_domain= (Caused by NewConnectionError('<urllib3.connection.VerifiedHTTPSConnection object at 0x107e144e0>: Failed to establish a new connection: [Errno 8] nodename nor servname provided, or not known'))

During handling of the above exception, another exception occurred:

Traceback (most recent call last):
  File "/Library/Frameworks/Python.framework/Versions/3.7/lib/python3.7/threading.py", line 917, in _bootstrap_inner
    self.run()
  File "spyderpro/people2.py", line 221, in run
    result = self._target(*self._args)
  File "spyderpro/people2.py", line 179, in count_headdata
    g = self.__get_heatdata_bytime(date, datetim, region_id)
  File "spyderpro/people2.py", line 167, in __get_heatdata_bytime
    g = self.request_heatdata(url)
  File "spyderpro/people2.py", line 151, in request_heatdata
    response = self.request.get(url=url, headers=self.headers)
  File "/Users/darkmoon/PycharmProjects/SpyderPro/venv/lib/python3.7/site-packages/requests/sessions.py", line 546, in get
    return self.request('GET', url, **kwargs)
  File "/Users/darkmoon/PycharmProjects/SpyderPro/venv/lib/python3.7/site-packages/requests/sessions.py", line 533, in request
    resp = self.send(prep, **send_kwargs)
  File "/Users/darkmoon/PycharmProjects/SpyderPro/venv/lib/python3.7/site-packages/requests/sessions.py", line 646, in send
    r = adapter.send(request, **kwargs)
  File "/Users/darkmoon/PycharmProjects/SpyderPro/venv/lib/python3.7/site-packages/requests/adapters.py", line 516, in send
    raise ConnectionError(e, request=request)
requests.exceptions.ConnectionError: HTTPSConnectionPool(host='heat.qq.com', port=443): Max retries exceeded with url: /api/getHeatDataByTime.php?region_id=1230&datetime=2018-08-04+08%3A45%3A00&sub_domain= (Caused by NewConnectionError('<urllib3.connection.VerifiedHTTPSConnection object at 0x107e144e0>: Failed to establish a new connection: [Errno 8] nodename nor servname provided, or not known'))

Exception in thread Thread-189382:
Traceback (most recent call last):
  File "/Users/darkmoon/PycharmProjects/SpyderPro/venv/lib/python3.7/site-packages/urllib3/connection.py", line 160, in _new_conn
    (self._dns_host, self.port), self.timeout, **extra_kw)
  File "/Users/darkmoon/PycharmProjects/SpyderPro/venv/lib/python3.7/site-packages/urllib3/util/connection.py", line 57, in create_connection
    for res in socket.getaddrinfo(host, port, family, socket.SOCK_STREAM):
  File "/Library/Frameworks/Python.framework/Versions/3.7/lib/python3.7/socket.py", line 748, in getaddrinfo
    for res in _socket.getaddrinfo(host, port, family, type, proto, flags):
socket.gaierror: [Errno 8] nodename nor servname provided, or not known

During handling of the above exception, another exception occurred:

Traceback (most recent call last):
  File "/Users/darkmoon/PycharmProjects/SpyderPro/venv/lib/python3.7/site-packages/urllib3/connectionpool.py", line 603, in urlopen
    chunked=chunked)
  File "/Users/darkmoon/PycharmProjects/SpyderPro/venv/lib/python3.7/site-packages/urllib3/connectionpool.py", line 344, in _make_request
    self._validate_conn(conn)
  File "/Users/darkmoon/PycharmProjects/SpyderPro/venv/lib/python3.7/site-packages/urllib3/connectionpool.py", line 843, in _validate_conn
    conn.connect()
  File "/Users/darkmoon/PycharmProjects/SpyderPro/venv/lib/python3.7/site-packages/urllib3/connection.py", line 316, in connect
    conn = self._new_conn()
  File "/Users/darkmoon/PycharmProjects/SpyderPro/venv/lib/python3.7/site-packages/urllib3/connection.py", line 169, in _new_conn
    self, "Failed to establish a new connection: %s" % e)
urllib3.exceptions.NewConnectionError: <urllib3.connection.VerifiedHTTPSConnection object at 0x107e142b0>: Failed to establish a new connection: [Errno 8] nodename nor servname provided, or not known

During handling of the above exception, another exception occurred:

Traceback (most recent call last):
  File "/Users/darkmoon/PycharmProjects/SpyderPro/venv/lib/python3.7/site-packages/requests/adapters.py", line 449, in send
    timeout=timeout
  File "/Users/darkmoon/PycharmProjects/SpyderPro/venv/lib/python3.7/site-packages/urllib3/connectionpool.py", line 641, in urlopen
    _stacktrace=sys.exc_info()[2])
  File "/Users/darkmoon/PycharmProjects/SpyderPro/venv/lib/python3.7/site-packages/urllib3/util/retry.py", line 399, in increment
    raise MaxRetryError(_pool, url, error or ResponseError(cause))
urllib3.exceptions.MaxRetryError: HTTPSConnectionPool(host='heat.qq.com', port=443): Max retries exceeded with url: /api/getHeatDataByTime.php?region_id=1230&datetime=2018-10-20+13%3A45%3A00&sub_domain= (Caused by NewConnectionError('<urllib3.connection.VerifiedHTTPSConnection object at 0x107e142b0>: Failed to establish a new connection: [Errno 8] nodename nor servname provided, or not known'))

During handling of the above exception, another exception occurred:

Traceback (most recent call last):
  File "/Library/Frameworks/Python.framework/Versions/3.7/lib/python3.7/threading.py", line 917, in _bootstrap_inner
    self.run()
  File "spyderpro/people2.py", line 221, in run
    result = self._target(*self._args)
  File "spyderpro/people2.py", line 179, in count_headdata
    g = self.__get_heatdata_bytime(date, datetim, region_id)
  File "spyderpro/people2.py", line 167, in __get_heatdata_bytime
    g = self.request_heatdata(url)
  File "spyderpro/people2.py", line 151, in request_heatdata
    response = self.request.get(url=url, headers=self.headers)
  File "/Users/darkmoon/PycharmProjects/SpyderPro/venv/lib/python3.7/site-packages/requests/sessions.py", line 546, in get
    return self.request('GET', url, **kwargs)
  File "/Users/darkmoon/PycharmProjects/SpyderPro/venv/lib/python3.7/site-packages/requests/sessions.py", line 533, in request
    resp = self.send(prep, **send_kwargs)
  File "/Users/darkmoon/PycharmProjects/SpyderPro/venv/lib/python3.7/site-packages/requests/sessions.py", line 646, in send
    r = adapter.send(request, **kwargs)
  File "/Users/darkmoon/PycharmProjects/SpyderPro/venv/lib/python3.7/site-packages/requests/adapters.py", line 516, in send
    raise ConnectionError(e, request=request)
requests.exceptions.ConnectionError: HTTPSConnectionPool(host='heat.qq.com', port=443): Max retries exceeded with url: /api/getHeatDataByTime.php?region_id=1230&datetime=2018-10-20+13%3A45%3A00&sub_domain= (Caused by NewConnectionError('<urllib3.connection.VerifiedHTTPSConnection object at 0x107e142b0>: Failed to establish a new connection: [Errno 8] nodename nor servname provided, or not known'))

Exception in thread Thread-227211:
Traceback (most recent call last):
  File "/Users/darkmoon/PycharmProjects/SpyderPro/venv/lib/python3.7/site-packages/urllib3/connection.py", line 160, in _new_conn
    (self._dns_host, self.port), self.timeout, **extra_kw)
  File "/Users/darkmoon/PycharmProjects/SpyderPro/venv/lib/python3.7/site-packages/urllib3/util/connection.py", line 57, in create_connection
    for res in socket.getaddrinfo(host, port, family, socket.SOCK_STREAM):
  File "/Library/Frameworks/Python.framework/Versions/3.7/lib/python3.7/socket.py", line 748, in getaddrinfo
    for res in _socket.getaddrinfo(host, port, family, type, proto, flags):
socket.gaierror: [Errno 8] nodename nor servname provided, or not known

During handling of the above exception, another exception occurred:

Traceback (most recent call last):
  File "/Users/darkmoon/PycharmProjects/SpyderPro/venv/lib/python3.7/site-packages/urllib3/connectionpool.py", line 603, in urlopen
    chunked=chunked)
  File "/Users/darkmoon/PycharmProjects/SpyderPro/venv/lib/python3.7/site-packages/urllib3/connectionpool.py", line 344, in _make_request
    self._validate_conn(conn)
  File "/Users/darkmoon/PycharmProjects/SpyderPro/venv/lib/python3.7/site-packages/urllib3/connectionpool.py", line 843, in _validate_conn
    conn.connect()
  File "/Users/darkmoon/PycharmProjects/SpyderPro/venv/lib/python3.7/site-packages/urllib3/connection.py", line 316, in connect
    conn = self._new_conn()
  File "/Users/darkmoon/PycharmProjects/SpyderPro/venv/lib/python3.7/site-packages/urllib3/connection.py", line 169, in _new_conn
    self, "Failed to establish a new connection: %s" % e)
urllib3.exceptions.NewConnectionError: <urllib3.connection.VerifiedHTTPSConnection object at 0x107e14128>: Failed to establish a new connection: [Errno 8] nodename nor servname provided, or not known

During handling of the above exception, another exception occurred:

Traceback (most recent call last):
  File "/Users/darkmoon/PycharmProjects/SpyderPro/venv/lib/python3.7/site-packages/requests/adapters.py", line 449, in send
    timeout=timeout
  File "/Users/darkmoon/PycharmProjects/SpyderPro/venv/lib/python3.7/site-packages/urllib3/connectionpool.py", line 641, in urlopen
    _stacktrace=sys.exc_info()[2])
  File "/Users/darkmoon/PycharmProjects/SpyderPro/venv/lib/python3.7/site-packages/urllib3/util/retry.py", line 399, in increment
    raise MaxRetryError(_pool, url, error or ResponseError(cause))
urllib3.exceptions.MaxRetryError: HTTPSConnectionPool(host='heat.qq.com', port=443): Max retries exceeded with url: /api/getHeatDataByTime.php?region_id=1230&datetime=2019-02-28+22%3A10%3A00&sub_domain= (Caused by NewConnectionError('<urllib3.connection.VerifiedHTTPSConnection object at 0x107e14128>: Failed to establish a new connection: [Errno 8] nodename nor servname provided, or not known'))

During handling of the above exception, another exception occurred:

Traceback (most recent call last):
  File "/Library/Frameworks/Python.framework/Versions/3.7/lib/python3.7/threading.py", line 917, in _bootstrap_inner
    self.run()
  File "spyderpro/people2.py", line 221, in run
    result = self._target(*self._args)
  File "spyderpro/people2.py", line 179, in count_headdata
    g = self.__get_heatdata_bytime(date, datetim, region_id)
  File "spyderpro/people2.py", line 167, in __get_heatdata_bytime
    g = self.request_heatdata(url)
  File "spyderpro/people2.py", line 151, in request_heatdata
    response = self.request.get(url=url, headers=self.headers)
  File "/Users/darkmoon/PycharmProjects/SpyderPro/venv/lib/python3.7/site-packages/requests/sessions.py", line 546, in get
    return self.request('GET', url, **kwargs)
  File "/Users/darkmoon/PycharmProjects/SpyderPro/venv/lib/python3.7/site-packages/requests/sessions.py", line 533, in request
    resp = self.send(prep, **send_kwargs)
  File "/Users/darkmoon/PycharmProjects/SpyderPro/venv/lib/python3.7/site-packages/requests/sessions.py", line 646, in send
    r = adapter.send(request, **kwargs)
  File "/Users/darkmoon/PycharmProjects/SpyderPro/venv/lib/python3.7/site-packages/requests/adapters.py", line 516, in send
    raise ConnectionError(e, request=request)
requests.exceptions.ConnectionError: HTTPSConnectionPool(host='heat.qq.com', port=443): Max retries exceeded with url: /api/getHeatDataByTime.php?region_id=1230&datetime=2019-02-28+22%3A10%3A00&sub_domain= (Caused by NewConnectionError('<urllib3.connection.VerifiedHTTPSConnection object at 0x107e14128>: Failed to establish a new connection: [Errno 8] nodename nor servname provided, or not known'))
